Workbook

Sheet trend
B5: =IFERROR(__xludf.DUMMYFUNCTION("UNIQUE(FILTER(template!$B$5:$B$38, NOT(ISBLANK(template!$B$5:$B$38)))) "),"Exercise") -> Exercise | C5: =template!$J$3 -> Week 1 | D5: =template!$Z$3 -> Week 2 | E5: =template!$AP$3 -> Week 3 | F5: =template!$BF$3 -> Week 4
B6: =IFERROR(__xludf.DUMMYFUNCTION("""COMPUTED_VALUE"""),"Leg press") -> Leg press | C6: =AVERAGEIF(template!$J:$J,B6,template!$Y:$Y) -> 0 | D6: =AVERAGEIF(template!$Z:$Z,B6,template!$AO:$AO) -> 0 | E6: =AVERAGEIF(template!$AP:$AP,B6,template!$BE:$BE) -> 0 | F6: =AVERAGEIF(template!$BF:$BF,B6,template!$BU:$BU) -> 0 | G6: =IF(SLOPE(C6:F6,{1;2;3;4}) > 0.5, "Significant Improvement", IF(SLOPE(C6:F6,{1;2;3;4}) > 0.1, "Slight Improvement", IF(SLOPE(C6:F6,{1;2;3;4}) >= -0.1, "Stable", IF(SLOPE(C6:F6,{1;2;3;4}) > -0.5, "Slight Decrease", "Significant Decrease")))) -> Stable
B7: =IFERROR(__xludf.DUMMYFUNCTION("""COMPUTED_VALUE"""),"Panca piana") -> Panca piana | C7: =AVERAGEIF(template!$J:$J,B7,template!$Y:$Y) -> 62.068966 | D7: =AVERAGEIF(template!$Z:$Z,B7,template!$AO:$AO) -> 0 | E7: =AVERAGEIF(template!$AP:$AP,B7,template!$BE:$BE) -> 0 | F7: =AVERAGEIF(template!$BF:$BF,B7,template!$BU:$BU) -> 0 | G7: =IF(SLOPE(C7:F7,{1;2;3;4}) > 0.5, "Significant Improvement", IF(SLOPE(C7:F7,{1;2;3;4}) > 0.1, "Slight Improvement", IF(SLOPE(C7:F7,{1;2;3;4}) >= -0.1, "Stable", IF(SLOPE(C7:F7,{1;2;3;4}) > -0.5, "Slight Decrease", "Significant Decrease")))) -> Significant Decrease
B8: =IFERROR(__xludf.DUMMYFUNCTION("""COMPUTED_VALUE"""),"Rematore [manubri]") -> Rematore [manubri] | C8: =AVERAGEIF(template!$J:$J,B8,template!$Y:$Y) -> 0 | D8: =AVERAGEIF(template!$Z:$Z,B8,template!$AO:$AO) -> 0 | E8: =AVERAGEIF(template!$AP:$AP,B8,template!$BE:$BE) -> 0 | F8: =AVERAGEIF(template!$BF:$BF,B8,template!$BU:$BU) -> 0 | G8: =IF(SLOPE(C8:F8,{1;2;3;4}) > 0.5, "Significant Improvement", IF(SLOPE(C8:F8,{1;2;3;4}) > 0.1, "Slight Improvement", IF(SLOPE(C8:F8,{1;2;3;4}) >= -0.1, "Stable", IF(SLOPE(C8:F8,{1;2;3;4}) > -0.5, "Slight Decrease", "Significant Decrease")))) -> Stable
B9: =IFERROR(__xludf.DUMMYFUNCTION("""COMPUTED_VALUE"""),"Shoulder press [manubri]") -> Shoulder press [manubri] | C9: =AVERAGEIF(template!$J:$J,B9,template!$Y:$Y) -> 0 | D9: =AVERAGEIF(template!$Z:$Z,B9,template!$AO:$AO) -> 0 | E9: =AVERAGEIF(template!$AP:$AP,B9,template!$BE:$BE) -> 0 | F9: =AVERAGEIF(template!$BF:$BF,B9,template!$BU:$BU) -> 0 | G9: =IF(SLOPE(C9:F9,{1;2;3;4}) > 0.5, "Significant Improvement", IF(SLOPE(C9:F9,{1;2;3;4}) > 0.1, "Slight Improvement", IF(SLOPE(C9:F9,{1;2;3;4}) >= -0.1, "Stable", IF(SLOPE(C9:F9,{1;2;3;4}) > -0.5, "Slight Decrease", "Significant Decrease")))) -> Stable
B10: =IFERROR(__xludf.DUMMYFUNCTION("""COMPUTED_VALUE"""),"Curl [manubri]") -> Curl [manubri] | C10: =AVERAGEIF(template!$J:$J,B10,template!$Y:$Y) -> 0 | D10: =AVERAGEIF(template!$Z:$Z,B10,template!$AO:$AO) -> 0 | E10: =AVERAGEIF(template!$AP:$AP,B10,template!$BE:$BE) -> 0 | F10: =AVERAGEIF(template!$BF:$BF,B10,template!$BU:$BU) -> 0 | G10: =IF(SLOPE(C10:F10,{1;2;3;4}) > 0.5, "Significant Improvement", IF(SLOPE(C10:F10,{1;2;3;4}) > 0.1, "Slight Improvement", IF(SLOPE(C10:F10,{1;2;3;4}) >= -0.1, "Stable", IF(SLOPE(C10:F10,{1;2;3;4}) > -0.5, "Slight Decrease", "Significant Decrease")))) -> Stable
B11: =IFERROR(__xludf.DUMMYFUNCTION("""COMPUTED_VALUE"""),"Plank") -> Plank | C11: =AVERAGEIF(template!$J:$J,B11,template!$Y:$Y) -> 0 | D11: =AVERAGEIF(template!$Z:$Z,B11,template!$AO:$AO) -> 0 | E11: =AVERAGEIF(template!$AP:$AP,B11,template!$BE:$BE) -> 0 | F11: =AVERAGEIF(template!$BF:$BF,B11,template!$BU:$BU) -> 0 | G11: =IF(SLOPE(C11:F11,{1;2;3;4}) > 0.5, "Significant Improvement", IF(SLOPE(C11:F11,{1;2;3;4}) > 0.1, "Slight Improvement", IF(SLOPE(C11:F11,{1;2;3;4}) >= -0.1, "Stable", IF(SLOPE(C11:F11,{1;2;3;4}) > -0.5, "Slight Decrease", "Significant Decrease")))) -> Stable
B12: =IFERROR(__xludf.DUMMYFUNCTION("""COMPUTED_VALUE"""),"Leg curl ") -> Leg curl | C12: =AVERAGEIF(template!$J:$J,B12,template!$Y:$Y) -> 0 | D12: =AVERAGEIF(template!$Z:$Z,B12,template!$AO:$AO) -> 0 | E12: =AVERAGEIF(template!$AP:$AP,B12,template!$BE:$BE) -> 0 | F12: =AVERAGEIF(template!$BF:$BF,B12,template!$BU:$BU) -> 0 | G12: =IF(SLOPE(C12:F12,{1;2;3;4}) > 0.5, "Significant Improvement", IF(SLOPE(C12:F12,{1;2;3;4}) > 0.1, "Slight Improvement", IF(SLOPE(C12:F12,{1;2;3;4}) >= -0.1, "Stable", IF(SLOPE(C12:F12,{1;2;3;4}) > -0.5, "Slight Decrease", "Significant Decrease")))) -> Stable
B13: =IFERROR(__xludf.DUMMYFUNCTION("""COMPUTED_VALUE"""),"Lat machine") -> Lat machine | C13: =AVERAGEIF(template!$J:$J,B13,template!$Y:$Y) -> 55.862069 | D13: =AVERAGEIF(template!$Z:$Z,B13,template!$AO:$AO) -> 0 | E13: =AVERAGEIF(template!$AP:$AP,B13,template!$BE:$BE) -> 0 | F13: =AVERAGEIF(template!$BF:$BF,B13,template!$BU:$BU) -> 0 | G13: =IF(SLOPE(C13:F13,{1;2;3;4}) > 0.5, "Significant Improvement", IF(SLOPE(C13:F13,{1;2;3;4}) > 0.1, "Slight Improvement", IF(SLOPE(C13:F13,{1;2;3;4}) >= -0.1, "Stable", IF(SLOPE(C13:F13,{1;2;3;4}) > -0.5, "Slight Decrease", "Significant Decrease")))) -> Significant Decrease
B14: =IFERROR(__xludf.DUMMYFUNCTION("""COMPUTED_VALUE"""),"Chest press") -> Chest press | C14: =AVERAGEIF(template!$J:$J,B14,template!$Y:$Y) -> 49.655172 | D14: =AVERAGEIF(template!$Z:$Z,B14,template!$AO:$AO) -> 0 | E14: =AVERAGEIF(template!$AP:$AP,B14,template!$BE:$BE) -> 0 | F14: =AVERAGEIF(template!$BF:$BF,B14,template!$BU:$BU) -> 0 | G14: =IF(SLOPE(C14:F14,{1;2;3;4}) > 0.5, "Significant Improvement", IF(SLOPE(C14:F14,{1;2;3;4}) > 0.1, "Slight Improvement", IF(SLOPE(C14:F14,{1;2;3;4}) >= -0.1, "Stable", IF(SLOPE(C14:F14,{1;2;3;4}) > -0.5, "Slight Decrease", "Significant Decrease")))) -> Significant Decrease
B15: =IFERROR(__xludf.DUMMYFUNCTION("""COMPUTED_VALUE"""),"Affondi [manubri]") -> Affondi [manubri] | C15: =AVERAGEIF(template!$J:$J,B15,template!$Y:$Y) -> 0 | D15: =AVERAGEIF(template!$Z:$Z,B15,template!$AO:$AO) -> 0 | E15: =AVERAGEIF(template!$AP:$AP,B15,template!$BE:$BE) -> 0 | F15: =AVERAGEIF(template!$BF:$BF,B15,template!$BU:$BU) -> 0 | G15: =IF(SLOPE(C15:F15,{1;2;3;4}) > 0.5, "Significant Improvement", IF(SLOPE(C15:F15,{1;2;3;4}) > 0.1, "Slight Improvement", IF(SLOPE(C15:F15,{1;2;3;4}) >= -0.1, "Stable", IF(SLOPE(C15:F15,{1;2;3;4}) > -0.5, "Slight Decrease", "Significant Decrease")))) -> Stable
B16: =IFERROR(__xludf.DUMMYFUNCTION("""COMPUTED_VALUE"""),"Estensioni tricipiti [cavi]") -> Estensioni tricipiti [cavi] | C16: =AVERAGEIF(template!$J:$J,B16,template!$Y:$Y) -> 0 | D16: =AVERAGEIF(template!$Z:$Z,B16,template!$AO:$AO) -> 0 | E16: =AVERAGEIF(template!$AP:$AP,B16,template!$BE:$BE) -> 0 | F16: =AVERAGEIF(template!$BF:$BF,B16,template!$BU:$BU) -> 0 | G16: =IF(SLOPE(C16:F16,{1;2;3;4}) > 0.5, "Significant Improvement", IF(SLOPE(C16:F16,{1;2;3;4}) > 0.1, "Slight Improvement", IF(SLOPE(C16:F16,{1;2;3;4}) >= -0.1, "Stable", IF(SLOPE(C16:F16,{1;2;3;4}) > -0.5, "Slight Decrease", "Significant Decrease")))) -> Stable
B17: =IFERROR(__xludf.DUMMYFUNCTION("""COMPUTED_VALUE"""),"Leg curl") -> Leg curl | C17: =AVERAGEIF(template!$J:$J,B17,template!$Y:$Y) -> 0 | D17: =AVERAGEIF(template!$Z:$Z,B17,template!$AO:$AO) -> 0 | E17: =AVERAGEIF(template!$AP:$AP,B17,template!$BE:$BE) -> 0 | F17: =AVERAGEIF(template!$BF:$BF,B17,template!$BU:$BU) -> 0 | G17: =IF(SLOPE(C17:F17,{1;2;3;4}) > 0.5, "Significant Improvement", IF(SLOPE(C17:F17,{1;2;3;4}) > 0.1, "Slight Improvement", IF(SLOPE(C17:F17,{1;2;3;4}) >= -0.1, "Stable", IF(SLOPE(C17:F17,{1;2;3;4}) > -0.5, "Slight Decrease", "Significant Decrease")))) -> Stable
B18: =IFERROR(__xludf.DUMMYFUNCTION("""COMPUTED_VALUE"""),"Panca inclinata [manubri]") -> Panca inclinata [manubri] | C18: =AVERAGEIF(template!$J:$J,B18,template!$Y:$Y) -> 0 | D18: =AVERAGEIF(template!$Z:$Z,B18,template!$AO:$AO) -> 0 | E18: =AVERAGEIF(template!$AP:$AP,B18,template!$BE:$BE) -> 0 | F18: =AVERAGEIF(template!$BF:$BF,B18,template!$BU:$BU) -> 0 | G18: =IF(SLOPE(C18:F18,{1;2;3;4}) > 0.5, "Significant Improvement", IF(SLOPE(C18:F18,{1;2;3;4}) > 0.1, "Slight Improvement", IF(SLOPE(C18:F18,{1;2;3;4}) >= -0.1, "Stable", IF(SLOPE(C18:F18,{1;2;3;4}) > -0.5, "Slight Decrease", "Significant Decrease")))) -> Stable
B19: =IFERROR(__xludf.DUMMYFUNCTION("""COMPUTED_VALUE"""),"Panca inclinata") -> Panca inclinata | C19: =AVERAGEIF(template!$J:$J,B19,template!$Y:$Y) -> 0 | D19: =AVERAGEIF(template!$Z:$Z,B19,template!$AO:$AO) -> 0 | E19: =AVERAGEIF(template!$AP:$AP,B19,template!$BE:$BE) -> 0 | F19: =AVERAGEIF(template!$BF:$BF,B19,template!$BU:$BU) -> 0 | G19: =IF(SLOPE(C19:F19,{1;2;3;4}) > 0.5, "Significant Improvement", IF(SLOPE(C19:F19,{1;2;3;4}) > 0.1, "Slight Improvement", IF(SLOPE(C19:F19,{1;2;3;4}) >= -0.1, "Stable", IF(SLOPE(C19:F19,{1;2;3;4}) > -0.5, "Slight Decrease", "Significant Decrease")))) -> Stable
B20: =IFERROR(__xludf.DUMMYFUNCTION("""COMPUTED_VALUE"""),"Pulley") -> Pulley | C20: =AVERAGEIF(template!$J:$J,B20,template!$Y:$Y) -> 0 | D20: =AVERAGEIF(template!$Z:$Z,B20,template!$AO:$AO) -> 0 | E20: =AVERAGEIF(template!$AP:$AP,B20,template!$BE:$BE) -> 0 | F20: =AVERAGEIF(template!$BF:$BF,B20,template!$BU:$BU) -> 0 | G20: =IF(SLOPE(C20:F20,{1;2;3;4}) > 0.5, "Significant Improvement", IF(SLOPE(C20:F20,{1;2;3;4}) > 0.1, "Slight Improvement", IF(SLOPE(C20:F20,{1;2;3;4}) >= -0.1, "Stable", IF(SLOPE(C20:F20,{1;2;3;4}) > -0.5, "Slight Decrease", "Significant Decrease")))) -> Stable
B21: =IFERROR(__xludf.DUMMYFUNCTION("""COMPUTED_VALUE"""),"7x7x7") -> 7x7x7 | C21: =AVERAGEIF(template!$J:$J,B21,template!$Y:$Y) -> 0 | D21: =AVERAGEIF(template!$Z:$Z,B21,template!$AO:$AO) -> 0 | E21: =AVERAGEIF(template!$AP:$AP,B21,template!$BE:$BE) -> 0 | F21: =AVERAGEIF(template!$BF:$BF,B21,template!$BU:$BU) -> 0 | G21: =IF(SLOPE(C21:F21,{1;2;3;4}) > 0.5, "Significant Improvement", IF(SLOPE(C21:F21,{1;2;3;4}) > 0.1, "Slight Improvement", IF(SLOPE(C21:F21,{1;2;3;4}) >= -0.1, "Stable", IF(SLOPE(C21:F21,{1;2;3;4}) > -0.5, "Slight Decrease", "Significant Decrease")))) -> Stable
B23: =IFERROR(__xludf.DUMMYFUNCTION("UNIQUE(FILTER(template!$B$5:$B$38, NOT(ISBLANK(template!$B$5:$B$38)))) "),"Exercise") -> Exercise | C23: =template!$J$3 -> Week 1 | D23: =template!$Z$3 -> Week 2 | E23: =template!$AP$3 -> Week 3 | F23: =template!$BF$3 -> Week 4
B24: =IFERROR(__xludf.DUMMYFUNCTION("""COMPUTED_VALUE"""),"Leg press") -> Leg press | C24: =SUMIF(template!$J:$J,B24,template!$X:$X) -> 0 | D24: =SUMIF(template!$Z:$Z,B24,template!$AN:$AN) -> 0 | E24: =SUMIF(template!$AP:$AP,B24,template!$BD:$BD) -> 0 | F24: =SUMIF(template!$BF:$BF,B24,template!$BT:$BT) -> 0
B25: =IFERROR(__xludf.DUMMYFUNCTION("""COMPUTED_VALUE"""),"Panca piana") -> Panca piana | C25: =SUMIF(template!$J:$J,B25,template!$X:$X) -> 664.81869 | D25: =SUMIF(template!$Z:$Z,B25,template!$AN:$AN) -> 0 | E25: =SUMIF(template!$AP:$AP,B25,template!$BD:$BD) -> 0 | F25: =SUMIF(template!$BF:$BF,B25,template!$BT:$BT) -> 0
B26: =IFERROR(__xludf.DUMMYFUNCTION("""COMPUTED_VALUE"""),"Rematore [manubri]") -> Rematore [manubri] | C26: =SUMIF(template!$J:$J,B26,template!$X:$X) -> 0 | D26: =SUMIF(template!$Z:$Z,B26,template!$AN:$AN) -> 0 | E26: =SUMIF(template!$AP:$AP,B26,template!$BD:$BD) -> 0 | F26: =SUMIF(template!$BF:$BF,B26,template!$BT:$BT) -> 0
B27: =IFERROR(__xludf.DUMMYFUNCTION("""COMPUTED_VALUE"""),"Shoulder press [manubri]") -> Shoulder press [manubri] | C27: =SUMIF(template!$J:$J,B27,template!$X:$X) -> 0 | D27: =SUMIF(template!$Z:$Z,B27,template!$AN:$AN) -> 0 | E27: =SUMIF(template!$AP:$AP,B27,template!$BD:$BD) -> 0 | F27: =SUMIF(template!$BF:$BF,B27,template!$BT:$BT) -> 0
B28: =IFERROR(__xludf.DUMMYFUNCTION("""COMPUTED_VALUE"""),"Curl [manubri]") -> Curl [manubri] | C28: =SUMIF(template!$J:$J,B28,template!$X:$X) -> 0 | D28: =SUMIF(template!$Z:$Z,B28,template!$AN:$AN) -> 0 | E28: =SUMIF(template!$AP:$AP,B28,template!$BD:$BD) -> 0 | F28: =SUMIF(template!$BF:$BF,B28,template!$BT:$BT) -> 0
B29: =IFERROR(__xludf.DUMMYFUNCTION("""COMPUTED_VALUE"""),"Plank") -> Plank | C29: =SUMIF(template!$J:$J,B29,template!$X:$X) -> 0 | D29: =SUMIF(template!$Z:$Z,B29,template!$AN:$AN) -> 0 | E29: =SUMIF(template!$AP:$AP,B29,template!$BD:$BD) -> 0 | F29: =SUMIF(template!$BF:$BF,B29,template!$BT:$BT) -> 0
B30: =IFERROR(__xludf.DUMMYFUNCTION("""COMPUTED_VALUE"""),"Leg curl ") -> Leg curl | C30: =SUMIF(template!$J:$J,B30,template!$X:$X) -> 0 | D30: =SUMIF(template!$Z:$Z,B30,template!$AN:$AN) -> 0 | E30: =SUMIF(template!$AP:$AP,B30,template!$BD:$BD) -> 0 | F30: =SUMIF(template!$BF:$BF,B30,template!$BT:$BT) -> 0
B31: =IFERROR(__xludf.DUMMYFUNCTION("""COMPUTED_VALUE"""),"Lat machine") -> Lat machine | C31: =SUMIF(template!$J:$J,B31,template!$X:$X) -> 1178.2951 | D31: =SUMIF(template!$Z:$Z,B31,template!$AN:$AN) -> 0 | E31: =SUMIF(template!$AP:$AP,B31,template!$BD:$BD) -> 0 | F31: =SUMIF(template!$BF:$BF,B31,template!$BT:$BT) -> 0
B32: =IFERROR(__xludf.DUMMYFUNCTION("""COMPUTED_VALUE"""),"Chest press") -> Chest press | C32: =SUMIF(template!$J:$J,B32,template!$X:$X) -> 711.65172 | D32: =SUMIF(template!$Z:$Z,B32,template!$AN:$AN) -> 0 | E32: =SUMIF(template!$AP:$AP,B32,template!$BD:$BD) -> 0 | F32: =SUMIF(template!$BF:$BF,B32,template!$BT:$BT) -> 0
B33: =IFERROR(__xludf.DUMMYFUNCTION("""COMPUTED_VALUE"""),"Affondi [manubri]") -> Affondi [manubri] | C33: =SUMIF(template!$J:$J,B33,template!$X:$X) -> 0 | D33: =SUMIF(template!$Z:$Z,B33,template!$AN:$AN) -> 0 | E33: =SUMIF(template!$AP:$AP,B33,template!$BD:$BD) -> 0 | F33: =SUMIF(template!$BF:$BF,B33,template!$BT:$BT) -> 0
B34: =IFERROR(__xludf.DUMMYFUNCTION("""COMPUTED_VALUE"""),"Estensioni tricipiti [cavi]") -> Estensioni tricipiti [cavi] | C34: =SUMIF(template!$J:$J,B34,template!$X:$X) -> 0 | D34: =SUMIF(template!$Z:$Z,B34,template!$AN:$AN) -> 0 | E34: =SUMIF(template!$AP:$AP,B34,template!$BD:$BD) -> 0 | F34: =SUMIF(template!$BF:$BF,B34,template!$BT:$BT) -> 0
B35: =IFERROR(__xludf.DUMMYFUNCTION("""COMPUTED_VALUE"""),"Leg curl") -> Leg curl | C35: =SUMIF(template!$J:$J,B35,template!$X:$X) -> 0 | D35: =SUMIF(template!$Z:$Z,B35,template!$AN:$AN) -> 0 | E35: =SUMIF(template!$AP:$AP,B35,template!$BD:$BD) -> 0 | F35: =SUMIF(template!$BF:$BF,B35,template!$BT:$BT) -> 0
B36: =IFERROR(__xludf.DUMMYFUNCTION("""COMPUTED_VALUE"""),"Panca inclinata [manubri]") -> Panca inclinata [manubri] | C36: =SUMIF(template!$J:$J,B36,template!$X:$X) -> 0 | D36: =SUMIF(template!$Z:$Z,B36,template!$AN:$AN) -> 0 | E36: =SUMIF(template!$AP:$AP,B36,template!$BD:$BD) -> 0 | F36: =SUMIF(template!$BF:$BF,B36,template!$BT:$BT) -> 0
B37: =IFERROR(__xludf.DUMMYFUNCTION("""COMPUTED_VALUE"""),"Panca inclinata") -> Panca inclinata | C37: =SUMIF(template!$J:$J,B37,template!$X:$X) -> 0 | D37: =SUMIF(template!$Z:$Z,B37,template!$AN:$AN) -> 0 | E37: =SUMIF(template!$AP:$AP,B37,template!$BD:$BD) -> 0 | F37: =SUMIF(template!$BF:$BF,B37,template!$BT:$BT) -> 0
B38: =IFERROR(__xludf.DUMMYFUNCTION("""COMPUTED_VALUE"""),"Pulley") -> Pulley | C38: =SUMIF(template!$J:$J,B38,template!$X:$X) -> 0 | D38: =SUMIF(template!$Z:$Z,B38,template!$AN:$AN) -> 0 | E38: =SUMIF(template!$AP:$AP,B38,template!$BD:$BD) -> 0 | F38: =SUMIF(template!$BF:$BF,B38,template!$BT:$BT) -> 0
B39: =IFERROR(__xludf.DUMMYFUNCTION("""COMPUTED_VALUE"""),"7x7x7") -> 7x7x7 | C39: =SUMIF(template!$J:$J,B39,template!$X:$X) -> 0 | D39: =SUMIF(template!$Z:$Z,B39,template!$AN:$AN) -> 0 | E39: =SUMIF(template!$AP:$AP,B39,template!$BD:$BD) -> 0 | F39: =SUMIF(template!$BF:$BF,B39,template!$BT:$BT) -> 0

Sheet template
J3: Week 1 | Z3: =IFERROR(__xludf.DUMMYFUNCTION("IFERROR(REGEXREPLACE(J3,""\d+$"",TEXT(VALUE(REGEXEXTRACT(J3,""\d+$""))+1,""0"")),""Block 1"")"),"Week 2") -> Week 2 | AP3: =IFERROR(__xludf.DUMMYFUNCTION("IFERROR(REGEXREPLACE(Z3,""\d+$"",TEXT(VALUE(REGEXEXTRACT(Z3,""\d+$""))+1,""0"")),""Block 1"")"),"Week 3") -> Week 3 | BF3: =IFERROR(__xludf.DUMMYFUNCTION("IFERROR(REGEXREPLACE(AP3,""\d+$"",TEXT(VALUE(REGEXEXTRACT(AP3,""\d+$""))+1,""0"")),""Block 1"")"),"Week 4") -> Week 4
J4: Exercise | K4: Sets | L4: Weight | M4: Reps | W4: Eff. Reps | X4: HVL | Y4: 1RM | Z4: Exercise | AA4: Sets | AB4: Weight | AC4: Reps | AM4: Eff. Reps | AN4: HVL | AO4: 1RM | AP4: Exercise | AQ4: Sets | AR4: Weight | AS4: Reps | BC4: Eff. Reps | BD4: HVL | BE4: 1RM | BF4: Exercise | BG4: Sets | BH4: Weight | BI4: Reps | BS4: Eff. Reps | BT4: HVL | BU4: 1RM
B5: Exercise | C5: 1RM | D5: 1st Rep Range | F5: Weight Stack Set | G5: Rounding | H5: Training Volume | I5: Maximum Sets
B6: Leg press | C6: 70 | D6: 0.83 | E6: 0.89 | F6: 150 | G6: 5 | H6: Moderate | J6: =$B6 -> Leg press | K6: =IF(ISNUMBER(M6),calculateSets(M6:V6,J$3,0,50%,$H6,$I6),1) -> 1 | L6: =IF(AND(ISNUMBER(C6),C6>0),calculateWeight(C6,$D6,$E6,$F6,$G6,0,J$3),0) -> 60 | W6: =IF(ISNUMBER(M6),calculateEffectiveRepetitions(M6:V6),0) -> 0 | X6: =IF(AND(ISNUMBER(M6),ISNUMBER(L6)),calculateHVL(M6:V6,L6),0) -> 0 | Y6: =IF(AND(ISNUMBER(L6),ISNUMBER(M6)),calculate1RM(L6,M6),0) -> 0 | Z6: =J6 -> Leg press | AA6: =IF(ISNUMBER(AC6),calculateSets(AC6:AL6,Z$3,0,50%,$H6,$I6),1) -> 1 | AB6: =IF(AND(ISNUMBER(Y6),Y6>0),calculateWeight(Y6,$D6,$E6,$F6,$G6,L6,Z$3),0) -> 0 | AM6: =IF(ISNUMBER(AC6),calculateEffectiveRepetitions(AC6:AL6),0) -> 0 | AN6: =IF(AND(ISNUMBER(AC6),ISNUMBER(AB6)),calculateHVL(AC6:AL6,AB6),0) -> 0 | AO6: =IF(AND(ISNUMBER(AB6),ISNUMBER(AC6)),calculate1RM(AB6,AC6),0) -> 0 | AP6: =Z6 -> Leg press | AQ6: =IF(ISNUMBER(AS6),calculateSets(AS6:BB6,AP$3,0,50%,$H6,$I6),1) -> 1 | AR6: =IF(AND(ISNUMBER(AO6),AO6>0),calculateWeight(AO6,$D6,$E6,$F6,$G6,AB6,AP$3),0) -> 0 | BC6: =IF(ISNUMBER(AS6),calculateEffectiveRepetitions(AS6:BB6),0) -> 0 | BD6: =IF(AND(ISNUMBER(AS6),ISNUMBER(AR6)),calculateHVL(AS6:BB6,AR6),0) -> 0 | BE6: =IF(AND(ISNUMBER(AR6),ISNUMBER(AS6)),calculate1RM(AR6,AS6),0) -> 0 | BF6: =AP6 -> Leg press | BG6: =IF(ISNUMBER(BI6),calculateSets(BI6:BR6,BF$3,0,50%,$H6,$I6),1) -> 1 | BH6: =IF(AND(ISNUMBER(BE6),BE6>0),calculateWeight(BE6,$D6,$E6,$F6,$G6,AR6,BF$3),0) -> 0 | BS6: =IF(ISNUMBER(BI6),calculateEffectiveRepetitions(BI6:BR6),0) -> 0 | BT6: =IF(AND(ISNUMBER(BI6),ISNUMBER(BH6)),calculateHVL(BI6:BR6,BH6),0) -> 0 | BU6: =IF(AND(ISNUMBER(BH6),ISNUMBER(BI6)),calculate1RM(BH6,BI6),0) -> 0
B7: Panca piana | C7: 50 | D7: 0.83 | E7: 0.89 | F7: 100 | G7: 10 | H7: Moderate | J7: =$B7 -> Panca piana | K7: =IF(ISNUMBER(M7),calculateSets(M7:V7,J$3,0,50%,$H7,$I7),1) -> 2 | L7: =IF(AND(ISNUMBER(C7),C7>0),calculateWeight(C7,$D7,$E7,$F7,$G7,0,J$3),0) -> 50 | M7: 8 | N7: 6 | W7: =IF(ISNUMBER(M7),calculateEffectiveRepetitions(M7:V7),0) -> 11.06 | X7: =IF(AND(ISNUMBER(M7),ISNUMBER(L7)),calculateHVL(M7:V7,L7),0) -> 664.81869 | Y7: =IF(AND(ISNUMBER(L7),ISNUMBER(M7)),calculate1RM(L7,M7),0) -> 62.068966 | Z7: =J7 -> Panca piana | AA7: =IF(ISNUMBER(AC7),calculateSets(AC7:AL7,Z$3,0,50%,$H7,$I7),1) -> 1 | AB7: =IF(AND(ISNUMBER(Y7),Y7>0),calculateWeight(Y7,$D7,$E7,$F7,$G7,L7,Z$3),0) -> 60 | AM7: =IF(ISNUMBER(AC7),calculateEffectiveRepetitions(AC7:AL7),0) -> 0 | AN7: =IF(AND(ISNUMBER(AC7),ISNUMBER(AB7)),calculateHVL(AC7:AL7,AB7),0) -> 0 | AO7: =IF(AND(ISNUMBER(AB7),ISNUMBER(AC7)),calculate1RM(AB7,AC7),0) -> 0 | AP7: =Z7 -> Panca piana | AQ7: =IF(ISNUMBER(AS7),calculateSets(AS7:BB7,AP$3,0,50%,$H7,$I7),1) -> 1 | AR7: =IF(AND(ISNUMBER(AO7),AO7>0),calculateWeight(AO7,$D7,$E7,$F7,$G7,AB7,AP$3),0) -> 0 | BC7: =IF(ISNUMBER(AS7),calculateEffectiveRepetitions(AS7:BB7),0) -> 0 | BD7: =IF(AND(ISNUMBER(AS7),ISNUMBER(AR7)),calculateHVL(AS7:BB7,AR7),0) -> 0 | BE7: =IF(AND(ISNUMBER(AR7),ISNUMBER(AS7)),calculate1RM(AR7,AS7),0) -> 0 | BF7: =AP7 -> Panca piana | BG7: =IF(ISNUMBER(BI7),calculateSets(BI7:BR7,BF$3,0,50%,$H7,$I7),1) -> 1 | BH7: =IF(AND(ISNUMBER(BE7),BE7>0),calculateWeight(BE7,$D7,$E7,$F7,$G7,AR7,BF$3),0) -> 0 | BS7: =IF(ISNUMBER(BI7),calculateEffectiveRepetitions(BI7:BR7),0) -> 0 | BT7: =IF(AND(ISNUMBER(BI7),ISNUMBER(BH7)),calculateHVL(BI7:BR7,BH7),0) -> 0 | BU7: =IF(AND(ISNUMBER(BH7),ISNUMBER(BI7)),calculate1RM(BH7,BI7),0) -> 0
B8: Rematore [manubri] | C8: 20 | D8: 0.83 | E8: 0.89 | F8: 100 | G8: 2 | H8: Moderate | J8: =$B8 -> Rematore [manubri] | K8: =IF(ISNUMBER(M8),calculateSets(M8:V8,J$3,W6,100%,$H8,$I8),1) -> 1 | L8: =IF(AND(ISNUMBER(C8),C8>0),calculateWeight(C8,$D8,$E8,$F8,$G8,0,J$3),0) -> 18 | W8: =IF(ISNUMBER(M8),calculateEffectiveRepetitions(M8:V8),0) -> 0 | X8: =IF(AND(ISNUMBER(M8),ISNUMBER(L8)),calculateHVL(M8:V8,L8),0) -> 0 | Y8: =IF(AND(ISNUMBER(L8),ISNUMBER(M8)),calculate1RM(L8,M8),0) -> 0 | Z8: =J8 -> Rematore [manubri] | AA8: =IF(ISNUMBER(AC8),calculateSets(AC8:AL8,Z$3,AM6,100%,$H8,$I8),1) -> 1 | AB8: =IF(AND(ISNUMBER(Y8),Y8>0),calculateWeight(Y8,$D8,$E8,$F8,$G8,L8,Z$3),0) -> 0 | AM8: =IF(ISNUMBER(AC8),calculateEffectiveRepetitions(AC8:AL8),0) -> 0 | AN8: =IF(AND(ISNUMBER(AC8),ISNUMBER(AB8)),calculateHVL(AC8:AL8,AB8),0) -> 0 | AO8: =IF(AND(ISNUMBER(AB8),ISNUMBER(AC8)),calculate1RM(AB8,AC8),0) -> 0 | AP8: =Z8 -> Rematore [manubri] | AQ8: =IF(ISNUMBER(AS8),calculateSets(AS8:BB8,AP$3,BC6,100%,$H8,$I8),1) -> 1 | AR8: =IF(AND(ISNUMBER(AO8),AO8>0),calculateWeight(AO8,$D8,$E8,$F8,$G8,AB8,AP$3),0) -> 0 | BC8: =IF(ISNUMBER(AS8),calculateEffectiveRepetitions(AS8:BB8),0) -> 0 | BD8: =IF(AND(ISNUMBER(AS8),ISNUMBER(AR8)),calculateHVL(AS8:BB8,AR8),0) -> 0 | BE8: =IF(AND(ISNUMBER(AR8),ISNUMBER(AS8)),calculate1RM(AR8,AS8),0) -> 0 | BF8: =AP8 -> Rematore [manubri] | BG8: =IF(ISNUMBER(BI8),calculateSets(BI8:BR8,BF$3,BS6,100%,$H8,$I8),1) -> 1 | BH8: =IF(AND(ISNUMBER(BE8),BE8>0),calculateWeight(BE8,$D8,$E8,$F8,$G8,AR8,BF$3),0) -> 0 | BS8: =IF(ISNUMBER(BI8),calculateEffectiveRepetitions(BI8:BR8),0) -> 0 | BT8: =IF(AND(ISNUMBER(BI8),ISNUMBER(BH8)),calculateHVL(BI8:BR8,BH8),0) -> 0 | BU8: =IF(AND(ISNUMBER(BH8),ISNUMBER(BI8)),calculate1RM(BH8,BI8),0) -> 0
B9: Shoulder press [manubri] | C9: 100 | D9: 0.83 | E9: 0.89 | F9: 100 | G9: 2.5 | H9: Moderate | J9: =$B9 -> Shoulder press [manubri] | K9: =IF(ISNUMBER(M9),calculateSets(M9:V9,J$3,W7,100%,$H9,$I9),1) -> 1 | L9: =IF(AND(ISNUMBER(C9),C9>0),calculateWeight(C9,$D9,$E9,$F9,$G9,0,J$3),0) -> 85 | W9: =IF(ISNUMBER(M9),calculateEffectiveRepetitions(M9:V9),0) -> 0 | X9: =IF(AND(ISNUMBER(M9),ISNUMBER(L9)),calculateHVL(M9:V9,L9),0) -> 0 | Y9: =IF(AND(ISNUMBER(L9),ISNUMBER(M9)),calculate1RM(L9,M9),0) -> 0 | Z9: =J9 -> Shoulder press [manubri] | AA9: =IF(ISNUMBER(AC9),calculateSets(AC9:AL9,Z$3,AM7,100%,$H9,$I9),1) -> 1 | AB9: =IF(AND(ISNUMBER(Y9),Y9>0),calculateWeight(Y9,$D9,$E9,$F9,$G9,L9,Z$3),0) -> 0 | AM9: =IF(ISNUMBER(AC9),calculateEffectiveRepetitions(AC9:AL9),0) -> 0 | AN9: =IF(AND(ISNUMBER(AC9),ISNUMBER(AB9)),calculateHVL(AC9:AL9,AB9),0) -> 0 | AO9: =IF(AND(ISNUMBER(AB9),ISNUMBER(AC9)),calculate1RM(AB9,AC9),0) -> 0 | AP9: =Z9 -> Shoulder press [manubri] | AQ9: =IF(ISNUMBER(AS9),calculateSets(AS9:BB9,AP$3,BC7,100%,$H9,$I9),1) -> 1 | AR9: =IF(AND(ISNUMBER(AO9),AO9>0),calculateWeight(AO9,$D9,$E9,$F9,$G9,AB9,AP$3),0) -> 0 | BC9: =IF(ISNUMBER(AS9),calculateEffectiveRepetitions(AS9:BB9),0) -> 0 | BD9: =IF(AND(ISNUMBER(AS9),ISNUMBER(AR9)),calculateHVL(AS9:BB9,AR9),0) -> 0 | BE9: =IF(AND(ISNUMBER(AR9),ISNUMBER(AS9)),calculate1RM(AR9,AS9),0) -> 0 | BF9: =AP9 -> Shoulder press [manubri] | BG9: =IF(ISNUMBER(BI9),calculateSets(BI9:BR9,BF$3,BS7,100%,$H9,$I9),1) -> 1 | BH9: =IF(AND(ISNUMBER(BE9),BE9>0),calculateWeight(BE9,$D9,$E9,$F9,$G9,AR9,BF$3),0) -> 0 | BS9: =IF(ISNUMBER(BI9),calculateEffectiveRepetitions(BI9:BR9),0) -> 0 | BT9: =IF(AND(ISNUMBER(BI9),ISNUMBER(BH9)),calculateHVL(BI9:BR9,BH9),0) -> 0 | BU9: =IF(AND(ISNUMBER(BH9),ISNUMBER(BI9)),calculate1RM(BH9,BI9),0) -> 0
B10: Curl [manubri] | C10: 80 | D10: 0.83 | E10: 0.89 | F10: 100 | G10: 2 | H10: Moderate | J10: =$B10 -> Curl [manubri] | K10: =IF(ISNUMBER(M10),calculateSets(M10:V10,J$3,0,50%,$H10,$I10),1) -> 1 | L10: =IF(AND(ISNUMBER(C10),C10>0),calculateWeight(C10,$D10,$E10,$F10,$G10,0,J$3),0) -> 68 | W10: =IF(ISNUMBER(M10),calculateEffectiveRepetitions(M10:V10),0) -> 0 | X10: =IF(AND(ISNUMBER(M10),ISNUMBER(L10)),calculateHVL(M10:V10,L10),0) -> 0 | Y10: =IF(AND(ISNUMBER(L10),ISNUMBER(M10)),calculate1RM(L10,M10),0) -> 0 | Z10: =J10 -> Curl [manubri] | AA10: =IF(ISNUMBER(AC10),calculateSets(AC10:AL10,Z$3,0,50%,$H10,$I10),1) -> 1 | AB10: =IF(AND(ISNUMBER(Y10),Y10>0),calculateWeight(Y10,$D10,$E10,$F10,$G10,L10,Z$3),0) -> 0 | AM10: =IF(ISNUMBER(AC10),calculateEffectiveRepetitions(AC10:AL10),0) -> 0 | AN10: =IF(AND(ISNUMBER(AC10),ISNUMBER(AB10)),calculateHVL(AC10:AL10,AB10),0) -> 0 | AO10: =IF(AND(ISNUMBER(AB10),ISNUMBER(AC10)),calculate1RM(AB10,AC10),0) -> 0 | AP10: =Z10 -> Curl [manubri] | AQ10: =IF(ISNUMBER(AS10),calculateSets(AS10:BB10,AP$3,0,50%,$H10,$I10),1) -> 1 | AR10: =IF(AND(ISNUMBER(AO10),AO10>0),calculateWeight(AO10,$D10,$E10,$F10,$G10,AB10,AP$3),0) -> 0 | BC10: =IF(ISNUMBER(AS10),calculateEffectiveRepetitions(AS10:BB10),0) -> 0 | BD10: =IF(AND(ISNUMBER(AS10),ISNUMBER(AR10)),calculateHVL(AS10:BB10,AR10),0) -> 0 | BE10: =IF(AND(ISNUMBER(AR10),ISNUMBER(AS10)),calculate1RM(AR10,AS10),0) -> 0 | BF10: =AP10 -> Curl [manubri] | BG10: =IF(ISNUMBER(BI10),calculateSets(BI10:BR10,BF$3,0,50%,$H10,$I10),1) -> 1 | BH10: =IF(AND(ISNUMBER(BE10),BE10>0),calculateWeight(BE10,$D10,$E10,$F10,$G10,AR10,BF$3),0) -> 0 | BS10: =IF(ISNUMBER(BI10),calculateEffectiveRepetitions(BI10:BR10),0) -> 0 | BT10: =IF(AND(ISNUMBER(BI10),ISNUMBER(BH10)),calculateHVL(BI10:BR10,BH10),0) -> 0 | BU10: =IF(AND(ISNUMBER(BH10),ISNUMBER(BI10)),calculate1RM(BH10,BI10),0) -> 0
B11: Plank | C11: 120 | H11: Moderate | I11: 6 | J11: =$B11 -> Plank | K11: =MIN( IF( SUM(OFFSET(K11, 0, 2, 1, 10)) < $C11*3, COUNTA(OFFSET(K11, 0, 2, 1, 10)) + 1, COUNTA(OFFSET(K11, 0, 2, 1, 10)) ), $I11 ) -> 1 | L11: =IF(AND(ISNUMBER(C11),C11>0),calculateWeight(C11,$D11,$E11,$F11,$G11,0,J$3),0) -> 0 | W11: =SUM(M11:V11) -> 0 | X11: =IF(AND(ISNUMBER(M11),ISNUMBER(L11)),calculateHVL(M11:V11,L11),0) -> 0 | Y11: =IF(AND(ISNUMBER(L11),ISNUMBER(M11)),calculate1RM(L11,M11),0) -> 0 | Z11: =J11 -> Plank | AA11: =MIN( IF( SUM(OFFSET(AA11, 0, 2, 1, 10)) < $C11*3, COUNTA(OFFSET(AA11, 0, 2, 1, 10)) + 1, COUNTA(OFFSET(AA11, 0, 2, 1, 10)) ), $I11 ) -> 1 | AB11: =IF(AND(ISNUMBER(Y11),Y11>0),calculateWeight(Y11,$D11,$E11,$F11,$G11,L11,Z$3),0) -> 0 | AM11: =SUM(AC11:AL11) -> 0 | AN11: =IF(AND(ISNUMBER(AC11),ISNUMBER(AB11)),calculateHVL(AC11:AL11,AB11),0) -> 0 | AO11: =IF(AND(ISNUMBER(AB11),ISNUMBER(AC11)),calculate1RM(AB11,AC11),0) -> 0 | AP11: =Z11 -> Plank | AQ11: =MIN( IF( SUM(OFFSET(AQ11, 0, 2, 1, 10)) < $C11*3, COUNTA(OFFSET(AQ11, 0, 2, 1, 10)) + 1, COUNTA(OFFSET(AQ11, 0, 2, 1, 10)) ), $I11 ) -> 1 | AR11: =IF(AND(ISNUMBER(AO11),AO11>0),calculateWeight(AO11,$D11,$E11,$F11,$G11,AB11,AP$3),0) -> 0 | BC11: =sum(AS11:BB11) -> 0 | BD11: =IF(AND(ISNUMBER(AS11),ISNUMBER(AR11)),calculateHVL(AS11:BB11,AR11),0) -> 0 | BE11: =IF(AND(ISNUMBER(AR11),ISNUMBER(AS11)),calculate1RM(AR11,AS11),0) -> 0 | BF11: =AP11 -> Plank | BG11: =MIN( IF( SUM(OFFSET(BG11, 0, 2, 1, 10)) < $C11*3, COUNTA(OFFSET(BG11, 0, 2, 1, 10)) + 1, COUNTA(OFFSET(BG11, 0, 2, 1, 10)) ), $I11 ) -> 1 | BH11: =IF(AND(ISNUMBER(BE11),BE11>0),calculateWeight(BE11,$D11,$E11,$F11,$G11,AR11,BF$3),0) -> 0 | BS11: =SUM(BI11:BR11) -> 0 | BT11: =IF(AND(ISNUMBER(BI11),ISNUMBER(BH11)),calculateHVL(BI11:BR11,BH11),0) -> 0 | BU11: =IF(AND(ISNUMBER(BH11),ISNUMBER(BI11)),calculate1RM(BH11,BI11),0) -> 0
J12: =J3 -> Week 1 | Z12: =Z3 -> Week 2 | AP12: =AP3 -> Week 3 | BF12: =BF3 -> Week 4
J13: Exercise | K13: Sets | L13: Weight | M13: Reps | W13: Eff. Reps | X13: HVL | Y13: 1RM | Z13: Exercise | AA13: Sets | AB13: Weight | AC13: Reps | AM13: Eff. Reps | AN13: HVL | AO13: 1RM | AP13: Exercise | AQ13: Sets | AR13: Weight | AS13: Reps | BC13: Eff. Reps | BD13: HVL | BE13: 1RM | BF13: Exercise | BG13: Sets | BH13: Weight | BI13: Reps | BS13: Eff. Reps | BT13: HVL | BU13: 1RM
B14: Exercise | C14: 1RM | D14: 1st Rep Range | F14: Weight Stack Set | G14: Rounding | H14: Training Volume | I14: Maximum Sets
B15: Leg curl | C15: 100 | D15: 0.83 | E15: 0.89 | F15: 100 | G15: 0.5 | H15: Moderate | J15: =$B15 -> Leg curl | K15: =IF(ISNUMBER(M15),calculateSets(M15:V15,J$3,W10,100%,$H15,$I15),1) -> 1 | L15: =IF(AND(ISNUMBER(C15),C15>0),calculateWeight(C15,$D15,$E15,$F15,$G15,0,J$3),0) -> 83 | W15: =IF(ISNUMBER(M15),calculateEffectiveRepetitions(M15:V15),0) -> 0 | X15: =IF(AND(ISNUMBER(M15),ISNUMBER(L15)),calculateHVL(M15:V15,L15),0) -> 0 | Y15: =IF(AND(ISNUMBER(L15),ISNUMBER(M15)),calculate1RM(L15,M15),0) -> 0 | Z15: =J15 -> Leg curl | AA15: =IF(ISNUMBER(AC15),calculateSets(AC15:AL15,Z$3,AM10,100%,$H15,$I15),1) -> 1 | AB15: =IF(AND(ISNUMBER(Y15),Y15>0),calculateWeight(Y15,$D15,$E15,$F15,$G15,L15,Z$3),0) -> 0 | AM15: =IF(ISNUMBER(AC15),calculateEffectiveRepetitions(AC15:AL15),0) -> 0 | AN15: =IF(AND(ISNUMBER(AC15),ISNUMBER(AB15)),calculateHVL(AC15:AL15,AB15),0) -> 0 | AO15: =IF(AND(ISNUMBER(AB15),ISNUMBER(AC15)),calculate1RM(AB15,AC15),0) -> 0 | AP15: =Z15 -> Leg curl | AQ15: =IF(ISNUMBER(AS15),calculateSets(AS15:BB15,AP$3,BC10,100%,$H15,$I15),1) -> 1 | AR15: =IF(AND(ISNUMBER(AO15),AO15>0),calculateWeight(AO15,$D15,$E15,$F15,$G15,AB15,AP$3),0) -> 0 | BC15: =IF(ISNUMBER(AS15),calculateEffectiveRepetitions(AS15:BB15),0) -> 0 | BD15: =IF(AND(ISNUMBER(AS15),ISNUMBER(AR15)),calculateHVL(AS15:BB15,AR15),0) -> 0 | BE15: =IF(AND(ISNUMBER(AR15),ISNUMBER(AS15)),calculate1RM(AR15,AS15),0) -> 0 | BF15: =AP15 -> Leg curl | BG15: =IF(ISNUMBER(BI15),calculateSets(BI15:BR15,BF$3,BS10,100%,$H15,$I15),1) -> 1 | BH15: =IF(AND(ISNUMBER(BE15),BE15>0),calculateWeight(BE15,$D15,$E15,$F15,$G15,AR15,BF$3),0) -> 0 | BS15: =IF(ISNUMBER(BI15),calculateEffectiveRepetitions(BI15:BR15),0) -> 0 | BT15: =IF(AND(ISNUMBER(BI15),ISNUMBER(BH15)),calculateHVL(BI15:BR15,BH15),0) -> 0 | BU15: =IF(AND(ISNUMBER(BH15),ISNUMBER(BI15)),calculate1RM(BH15,BI15),0) -> 0
B16: Lat machine | C16: 50 | D16: 0.83 | E16: 0.89 | F16: 100 | G16: 5 | H16: Moderate | J16: =$B16 -> Lat machine | K16: =IF(ISNUMBER(M16),calculateSets(M16:V16,J$3,W11,100%,$H16,$I16),1) -> 4 | L16: =IF(AND(ISNUMBER(C16),C16>0),calculateWeight(C16,$D16,$E16,$F16,$G16,0,J$3),0) -> 45 | M16: 8 | N16: 8 | O16: 7 | P16: 5 | W16: =IF(ISNUMBER(M16),calculateEffectiveRepetitions(M16:V16),0) -> 21.73 | X16: =IF(AND(ISNUMBER(M16),ISNUMBER(L16)),calculateHVL(M16:V16,L16),0) -> 1178.2951 | Y16: =IF(AND(ISNUMBER(L16),ISNUMBER(M16)),calculate1RM(L16,M16),0) -> 55.862069 | Z16: =J16 -> Lat machine | AA16: =IF(ISNUMBER(AC16),calculateSets(AC16:AL16,Z$3,AM11,100%,$H16,$I16),1) -> 1 | AB16: =IF(AND(ISNUMBER(Y16),Y16>0),calculateWeight(Y16,$D16,$E16,$F16,$G16,L16,Z$3),0) -> 50 | AM16: =IF(ISNUMBER(AC16),calculateEffectiveRepetitions(AC16:AL16),0) -> 0 | AN16: =IF(AND(ISNUMBER(AC16),ISNUMBER(AB16)),calculateHVL(AC16:AL16,AB16),0) -> 0 | AO16: =IF(AND(ISNUMBER(AB16),ISNUMBER(AC16)),calculate1RM(AB16,AC16),0) -> 0 | AP16: =Z16 -> Lat machine | AQ16: =IF(ISNUMBER(AS16),calculateSets(AS16:BB16,AP$3,BC11,100%,$H16,$I16),1) -> 1 | AR16: =IF(AND(ISNUMBER(AO16),AO16>0),calculateWeight(AO16,$D16,$E16,$F16,$G16,AB16,AP$3),0) -> 0 | BC16: =IF(ISNUMBER(AS16),calculateEffectiveRepetitions(AS16:BB16),0) -> 0 | BD16: =IF(AND(ISNUMBER(AS16),ISNUMBER(AR16)),calculateHVL(AS16:BB16,AR16),0) -> 0 | BE16: =IF(AND(ISNUMBER(AR16),ISNUMBER(AS16)),calculate1RM(AR16,AS16),0) -> 0 | BF16: =AP16 -> Lat machine | BG16: =IF(ISNUMBER(BI16),calculateSets(BI16:BR16,BF$3,BS11,100%,$H16,$I16),1) -> 1 | BH16: =IF(AND(ISNUMBER(BE16),BE16>0),calculateWeight(BE16,$D16,$E16,$F16,$G16,AR16,BF$3),0) -> 0 | BS16: =IF(ISNUMBER(BI16),calculateEffectiveRepetitions(BI16:BR16),0) -> 0 | BT16: =IF(AND(ISNUMBER(BI16),ISNUMBER(BH16)),calculateHVL(BI16:BR16,BH16),0) -> 0 | BU16: =IF(AND(ISNUMBER(BH16),ISNUMBER(BI16)),calculate1RM(BH16,BI16),0) -> 0
B17: Chest press | C17: 40 | D17: 0.83 | E17: 0.89 | F17: 100 | G17: 10 | H17: Moderate | J17: =$B17 -> Chest press | K17: =IF(ISNUMBER(M17),calculateSets(M17:V17,J$3,0,50%,$H17,$I17),1) -> 3 | L17: =IF(AND(ISNUMBER(C17),C17>0),calculateWeight(C17,$D17,$E17,$F17,$G17,0,J$3),0) -> 40 | M17: 8 | N17: 5 | O17: 5 | W17: =IF(ISNUMBER(M17),calculateEffectiveRepetitions(M17:V17),0) -> 15.23 | X17: =IF(AND(ISNUMBER(M17),ISNUMBER(L17)),calculateHVL(M17:V17,L17),0) -> 711.65172 | Y17: =IF(AND(ISNUMBER(L17),ISNUMBER(M17)),calculate1RM(L17,M17),0) -> 49.655172 | Z17: =J17 -> Chest press | AA17: =IF(ISNUMBER(AC17),calculateSets(AC17:AL17,Z$3,0,50%,$H17,$I17),1) -> 1 | AB17: =IF(AND(ISNUMBER(Y17),Y17>0),calculateWeight(Y17,$D17,$E17,$F17,$G17,L17,Z$3),0) -> 50 | AM17: =IF(ISNUMBER(AC17),calculateEffectiveRepetitions(AC17:AL17),0) -> 0 | AN17: =IF(AND(ISNUMBER(AC17),ISNUMBER(AB17)),calculateHVL(AC17:AL17,AB17),0) -> 0 | AO17: =IF(AND(ISNUMBER(AB17),ISNUMBER(AC17)),calculate1RM(AB17,AC17),0) -> 0 | AP17: =Z17 -> Chest press | AQ17: =IF(ISNUMBER(AS17),calculateSets(AS17:BB17,AP$3,0,50%,$H17,$I17),1) -> 1 | AR17: =IF(AND(ISNUMBER(AO17),AO17>0),calculateWeight(AO17,$D17,$E17,$F17,$G17,AB17,AP$3),0) -> 0 | BC17: =IF(ISNUMBER(AS17),calculateEffectiveRepetitions(AS17:BB17),0) -> 0 | BD17: =IF(AND(ISNUMBER(AS17),ISNUMBER(AR17)),calculateHVL(AS17:BB17,AR17),0) -> 0 | BE17: =IF(AND(ISNUMBER(AR17),ISNUMBER(AS17)),calculate1RM(AR17,AS17),0) -> 0 | BF17: =AP17 -> Chest press | BG17: =IF(ISNUMBER(BI17),calculateSets(BI17:BR17,BF$3,0,50%,$H17,$I17),1) -> 1 | BH17: =IF(AND(ISNUMBER(BE17),BE17>0),calculateWeight(BE17,$D17,$E17,$F17,$G17,AR17,BF$3),0) -> 0 | BS17: =IF(ISNUMBER(BI17),calculateEffectiveRepetitions(BI17:BR17),0) -> 0 | BT17: =IF(AND(ISNUMBER(BI17),ISNUMBER(BH17)),calculateHVL(BI17:BR17,BH17),0) -> 0 | BU17: =IF(AND(ISNUMBER(BH17),ISNUMBER(BI17)),calculate1RM(BH17,BI17),0) -> 0
B18: Affondi [manubri] | C18: 100 | D18: 0.83 | E18: 0.89 | F18: 100 | G18: 0.5 | H18: Moderate | J18: =$B18 -> Affondi [manubri] | K18: =IF(ISNUMBER(M18),calculateSets(M18:V18,J$3,SUM(W10,W15)*50%,100%,$H18,$I18),1) -> 1 | L18: =IF(AND(ISNUMBER(C18),C18>0),calculateWeight(C18,$D18,$E18,$F18,$G18,0,J$3),0) -> 83 | W18: =IF(ISNUMBER(M18),calculateEffectiveRepetitions(M18:V18),0) -> 0 | X18: =IF(AND(ISNUMBER(M18),ISNUMBER(L18)),calculateHVL(M18:V18,L18),0) -> 0 | Y18: =IF(AND(ISNUMBER(L18),ISNUMBER(M18)),calculate1RM(L18,M18),0) -> 0 | Z18: =J18 -> Affondi [manubri] | AA18: =IF(ISNUMBER(AC18),calculateSets(AC18:AL18,Z$3,SUM(AM10,AM15)*50%,100%,$H18,$I18),1) -> 1 | AB18: =IF(AND(ISNUMBER(Y18),Y18>0),calculateWeight(Y18,$D18,$E18,$F18,$G18,L18,Z$3),0) -> 0 | AM18: =IF(ISNUMBER(AC18),calculateEffectiveRepetitions(AC18:AL18),0) -> 0 | AN18: =IF(AND(ISNUMBER(AC18),ISNUMBER(AB18)),calculateHVL(AC18:AL18,AB18),0) -> 0 | AO18: =IF(AND(ISNUMBER(AB18),ISNUMBER(AC18)),calculate1RM(AB18,AC18),0) -> 0 | AP18: =Z18 -> Affondi [manubri] | AQ18: =IF(ISNUMBER(AS18),calculateSets(AS18:BB18,AP$3,SUM(BC10,BC15)*50%,100%,$H18,$I18),1) -> 1 | AR18: =IF(AND(ISNUMBER(AO18),AO18>0),calculateWeight(AO18,$D18,$E18,$F18,$G18,AB18,AP$3),0) -> 0 | BC18: =IF(ISNUMBER(AS18),calculateEffectiveRepetitions(AS18:BB18),0) -> 0 | BD18: =IF(AND(ISNUMBER(AS18),ISNUMBER(AR18)),calculateHVL(AS18:BB18,AR18),0) -> 0 | BE18: =IF(AND(ISNUMBER(AR18),ISNUMBER(AS18)),calculate1RM(AR18,AS18),0) -> 0 | BF18: =AP18 -> Affondi [manubri] | BG18: =IF(ISNUMBER(BI18),calculateSets(BI18:BR18,BF$3,SUM(BS10,BS15)*50%,100%,$H18,$I18),1) -> 1 | BH18: =IF(AND(ISNUMBER(BE18),BE18>0),calculateWeight(BE18,$D18,$E18,$F18,$G18,AR18,BF$3),0) -> 0 | BS18: =IF(ISNUMBER(BI18),calculateEffectiveRepetitions(BI18:BR18),0) -> 0 | BT18: =IF(AND(ISNUMBER(BI18),ISNUMBER(BH18)),calculateHVL(BI18:BR18,BH18),0) -> 0 | BU18: =IF(AND(ISNUMBER(BH18),ISNUMBER(BI18)),calculate1RM(BH18,BI18),0) -> 0
B19: Estensioni tricipiti [cavi] | C19: 100 | D19: 0.83 | E19: 0.89 | F19: 100 | G19: 0.5 | H19: Moderate | J19: =$B19 -> Estensioni tricipiti [cavi] | K19: =IF(ISNUMBER(M19),calculateSets(M19:V19,J$3,W17,100%,$H19,$I19),1) -> 1 | L19: =IF(AND(ISNUMBER(C19),C19>0),calculateWeight(C19,$D19,$E19,$F19,$G19,0,J$3),0) -> 83 | W19: =IF(ISNUMBER(M19),calculateEffectiveRepetitions(M19:V19),0) -> 0 | X19: =IF(AND(ISNUMBER(M19),ISNUMBER(L19)),calculateHVL(M19:V19,L19),0) -> 0 | Y19: =IF(AND(ISNUMBER(L19),ISNUMBER(M19)),calculate1RM(L19,M19),0) -> 0 | Z19: =J19 -> Estensioni tricipiti [cavi] | AA19: =IF(ISNUMBER(AC19),calculateSets(AC19:AL19,Z$3,AM17,100%,$H19,$I19),1) -> 1 | AB19: =IF(AND(ISNUMBER(Y19),Y19>0),calculateWeight(Y19,$D19,$E19,$F19,$G19,L19,Z$3),0) -> 0 | AM19: =IF(ISNUMBER(AC19),calculateEffectiveRepetitions(AC19:AL19),0) -> 0 | AN19: =IF(AND(ISNUMBER(AC19),ISNUMBER(AB19)),calculateHVL(AC19:AL19,AB19),0) -> 0 | AO19: =IF(AND(ISNUMBER(AB19),ISNUMBER(AC19)),calculate1RM(AB19,AC19),0) -> 0 | AP19: =Z19 -> Estensioni tricipiti [cavi] | AQ19: =IF(ISNUMBER(AS19),calculateSets(AS19:BB19,AP$3,BC17,100%,$H19,$I19),1) -> 1 | AR19: =IF(AND(ISNUMBER(AO19),AO19>0),calculateWeight(AO19,$D19,$E19,$F19,$G19,AB19,AP$3),0) -> 0 | BC19: =IF(ISNUMBER(AS19),calculateEffectiveRepetitions(AS19:BB19),0) -> 0 | BD19: =IF(AND(ISNUMBER(AS19),ISNUMBER(AR19)),calculateHVL(AS19:BB19,AR19),0) -> 0 | BE19: =IF(AND(ISNUMBER(AR19),ISNUMBER(AS19)),calculate1RM(AR19,AS19),0) -> 0 | BF19: =AP19 -> Estensioni tricipiti [cavi] | BG19: =IF(ISNUMBER(BI19),calculateSets(BI19:BR19,BF$3,BS17,100%,$H19,$I19),1) -> 1 | BH19: =IF(AND(ISNUMBER(BE19),BE19>0),calculateWeight(BE19,$D19,$E19,$F19,$G19,AR19,BF$3),0) -> 0 | BS19: =IF(ISNUMBER(BI19),calculateEffectiveRepetitions(BI19:BR19),0) -> 0 | BT19: =IF(AND(ISNUMBER(BI19),ISNUMBER(BH19)),calculateHVL(BI19:BR19,BH19),0) -> 0 | BU19: =IF(AND(ISNUMBER(BH19),ISNUMBER(BI19)),calculate1RM(BH19,BI19),0) -> 0
B20: Plank | C20: =C11 -> 120 | H20: Moderate | I20: 6 | J20: =$B20 -> Plank | K20: =MIN( IF( SUM(OFFSET(K20, 0, 2, 1, 10)) < $C20*3, COUNTA(OFFSET(K20, 0, 2, 1, 10)) + 1, COUNTA(OFFSET(K20, 0, 2, 1, 10)) ), $I20 ) -> 1 | L20: =IF(AND(ISNUMBER(C20),C20>0),calculateWeight(C20,$D20,$E20,$F20,$G20,0,J$3),0) -> 0 | W20: =SUM(M20:V20) -> 0 | X20: =IF(AND(ISNUMBER(M20),ISNUMBER(L20)),calculateHVL(M20:V20,L20),0) -> 0 | Y20: =IF(AND(ISNUMBER(L20),ISNUMBER(M20)),calculate1RM(L20,M20),0) -> 0 | Z20: =J20 -> Plank | AA20: =MIN( IF( SUM(OFFSET(AA20, 0, 2, 1, 10)) < $C20*3, COUNTA(OFFSET(AA20, 0, 2, 1, 10)) + 1, COUNTA(OFFSET(AA20, 0, 2, 1, 10)) ), $I20 ) -> 1 | AB20: =IF(AND(ISNUMBER(Y20),Y20>0),calculateWeight(Y20,$D20,$E20,$F20,$G20,L20,Z$3),0) -> 0 | AM20: =SUM(AC20:AL20) -> 0 | AN20: =IF(AND(ISNUMBER(AC20),ISNUMBER(AB20)),calculateHVL(AC20:AL20,AB20),0) -> 0 | AO20: =IF(AND(ISNUMBER(AB20),ISNUMBER(AC20)),calculate1RM(AB20,AC20),0) -> 0 | AP20: =Z20 -> Plank | AQ20: =MIN( IF( SUM(OFFSET(AQ20, 0, 2, 1, 10)) < $C20*3, COUNTA(OFFSET(AQ20, 0, 2, 1, 10)) + 1, COUNTA(OFFSET(AQ20, 0, 2, 1, 10)) ), $I20 ) -> 1 | AR20: =IF(AND(ISNUMBER(AO20),AO20>0),calculateWeight(AO20,$D20,$E20,$F20,$G20,AB20,AP$3),0) -> 0 | BC20: =sum(AS20:BB20) -> 0 | BD20: =IF(AND(ISNUMBER(AS20),ISNUMBER(AR20)),calculateHVL(AS20:BB20,AR20),0) -> 0 | BE20: =IF(AND(ISNUMBER(AR20),ISNUMBER(AS20)),calculate1RM(AR20,AS20),0) -> 0 | BF20: =AP20 -> Plank | BG20: =MIN( IF( SUM(OFFSET(BG20, 0, 2, 1, 10)) < $C20*3, COUNTA(OFFSET(BG20, 0, 2, 1, 10)) + 1, COUNTA(OFFSET(BG20, 0, 2, 1, 10)) ), $I20 ) -> 1 | BH20: =IF(AND(ISNUMBER(BE20),BE20>0),calculateWeight(BE20,$D20,$E20,$F20,$G20,AR20,BF$3),0) -> 0 | BS20: =SUM(BI20:BR20) -> 0 | BT20: =IF(AND(ISNUMBER(BI20),ISNUMBER(BH20)),calculateHVL(BI20:BR20,BH20),0) -> 0 | BU20: =IF(AND(ISNUMBER(BH20),ISNUMBER(BI20)),calculate1RM(BH20,BI20),0) -> 0
J21: =J3 -> Week 1 | Z21: =Z3 -> Week 2 | AP21: =AP3 -> Week 3 | BF21: =BF3 -> Week 4
J22: Exercise | K22: Sets | L22: Weight | M22: Reps | W22: Eff. Reps | X22: HVL | Y22: 1RM | Z22: Exercise | AA22: Sets | AB22: Weight | AC22: Reps | AM22: Eff. Reps | AN22: HVL | AO22: 1RM | AP22: Exercise | AQ22: Sets | AR22: Weight | AS22: Reps | BC22: Eff. Reps | BD22: HVL | BE22: 1RM | BF22: Exercise | BG22: Sets | BH22: Weight | BI22: Reps | BS22: Eff. Reps | BT22: HVL | BU22: 1RM
B23: Exercise | C23: 1RM | D23: 1st Rep Range | F23: Weight Stack Set | G23: Rounding | H23: Training Volume | I23: Maximum Sets
B24: Leg press | C24: 100 | D24: 0.83 | E24: 0.89 | F24: 100 | G24: 0.5 | H24: Moderate | J24: =$B24 -> Leg press | K24: =IF(ISNUMBER(M24),calculateSets(M24:V24,J$3,0,50%,$H24,$I24),1) -> 1 | L24: =IF(AND(ISNUMBER(C24),C24>0),calculateWeight(C24,$D24,$E24,$F24,$G24,0,J$3),0) -> 83 | W24: =IF(ISNUMBER(M24),calculateEffectiveRepetitions(M24:V24),0) -> 0 | X24: =IF(AND(ISNUMBER(M24),ISNUMBER(L24)),calculateHVL(M24:V24,L24),0) -> 0 | Y24: =IF(AND(ISNUMBER(L24),ISNUMBER(M24)),calculate1RM(L24,M24),0) -> 0 | Z24: =J24 -> Leg press | AA24: =IF(ISNUMBER(AC24),calculateSets(AC24:AL24,Z$3,0,50%,$H24,$I24),1) -> 1 | AB24: =IF(AND(ISNUMBER(Y24),Y24>0),calculateWeight(Y24,$D24,$E24,$F24,$G24,L24,Z$3),0) -> 0 | AM24: =IF(ISNUMBER(AC24),calculateEffectiveRepetitions(AC24:AL24),0) -> 0 | AN24: =IF(AND(ISNUMBER(AC24),ISNUMBER(AB24)),calculateHVL(AC24:AL24,AB24),0) -> 0 | AO24: =IF(AND(ISNUMBER(AB24),ISNUMBER(AC24)),calculate1RM(AB24,AC24),0) -> 0 | AP24: =Z24 -> Leg press | AQ24: =IF(ISNUMBER(AS24),calculateSets(AS24:BB24,AP$3,0,50%,$H24,$I24),1) -> 1 | AR24: =IF(AND(ISNUMBER(AO24),AO24>0),calculateWeight(AO24,$D24,$E24,$F24,$G24,AB24,AP$3),0) -> 0 | BC24: =IF(ISNUMBER(AS24),calculateEffectiveRepetitions(AS24:BB24),0) -> 0 | BD24: =IF(AND(ISNUMBER(AS24),ISNUMBER(AR24)),calculateHVL(AS24:BB24,AR24),0) -> 0 | BE24: =IF(AND(ISNUMBER(AR24),ISNUMBER(AS24)),calculate1RM(AR24,AS24),0) -> 0 | BF24: =AP24 -> Leg press | BG24: =IF(ISNUMBER(BI24),calculateSets(BI24:BR24,BF$3,0,50%,$H24,$I24),1) -> 1 | BH24: =IF(AND(ISNUMBER(BE24),BE24>0),calculateWeight(BE24,$D24,$E24,$F24,$G24,AR24,BF$3),0) -> 0 | BS24: =IF(ISNUMBER(BI24),calculateEffectiveRepetitions(BI24:BR24),0) -> 0 | BT24: =IF(AND(ISNUMBER(BI24),ISNUMBER(BH24)),calculateHVL(BI24:BR24,BH24),0) -> 0 | BU24: =IF(AND(ISNUMBER(BH24),ISNUMBER(BI24)),calculate1RM(BH24,BI24),0) -> 0
B25: Leg curl | C25: 100 | D25: 0.83 | E25: 0.89 | F25: 100 | G25: 0.5 | H25: Moderate | J25: =$B25 -> Leg curl | K25: =IF(ISNUMBER(M25),calculateSets(M25:V25,J$3,0,50%,$H25,$I25),1) -> 1 | L25: =IF(AND(ISNUMBER(C25),C25>0),calculateWeight(C25,$D25,$E25,$F25,$G25,0,J$3),0) -> 83 | W25: =IF(ISNUMBER(M25),calculateEffectiveRepetitions(M25:V25),0) -> 0 | X25: =IF(AND(ISNUMBER(M25),ISNUMBER(L25)),calculateHVL(M25:V25,L25),0) -> 0 | Y25: =IF(AND(ISNUMBER(L25),ISNUMBER(M25)),calculate1RM(L25,M25),0) -> 0 | Z25: =J25 -> Leg curl | AA25: =IF(ISNUMBER(AC25),calculateSets(AC25:AL25,Z$3,0,50%,$H25,$I25),1) -> 1 | AB25: =IF(AND(ISNUMBER(Y25),Y25>0),calculateWeight(Y25,$D25,$E25,$F25,$G25,L25,Z$3),0) -> 0 | AM25: =IF(ISNUMBER(AC25),calculateEffectiveRepetitions(AC25:AL25),0) -> 0 | AN25: =IF(AND(ISNUMBER(AC25),ISNUMBER(AB25)),calculateHVL(AC25:AL25,AB25),0) -> 0 | AO25: =IF(AND(ISNUMBER(AB25),ISNUMBER(AC25)),calculate1RM(AB25,AC25),0) -> 0 | AP25: =Z25 -> Leg curl | AQ25: =IF(ISNUMBER(AS25),calculateSets(AS25:BB25,AP$3,0,50%,$H25,$I25),1) -> 1 | AR25: =IF(AND(ISNUMBER(AO25),AO25>0),calculateWeight(AO25,$D25,$E25,$F25,$G25,AB25,AP$3),0) -> 0 | BC25: =IF(ISNUMBER(AS25),calculateEffectiveRepetitions(AS25:BB25),0) -> 0 | BD25: =IF(AND(ISNUMBER(AS25),ISNUMBER(AR25)),calculateHVL(AS25:BB25,AR25),0) -> 0 | BE25: =IF(AND(ISNUMBER(AR25),ISNUMBER(AS25)),calculate1RM(AR25,AS25),0) -> 0 | BF25: =AP25 -> Leg curl | BG25: =IF(ISNUMBER(BI25),calculateSets(BI25:BR25,BF$3,0,50%,$H25,$I25),1) -> 1 | BH25: =IF(AND(ISNUMBER(BE25),BE25>0),calculateWeight(BE25,$D25,$E25,$F25,$G25,AR25,BF$3),0) -> 0 | BS25: =IF(ISNUMBER(BI25),calculateEffectiveRepetitions(BI25:BR25),0) -> 0 | BT25: =IF(AND(ISNUMBER(BI25),ISNUMBER(BH25)),calculateHVL(BI25:BR25,BH25),0) -> 0 | BU25: =IF(AND(ISNUMBER(BH25),ISNUMBER(BI25)),calculate1RM(BH25,BI25),0) -> 0
B26: Panca inclinata [manubri] | C26: 100 | D26: 0.83 | E26: 0.89 | F26: 100 | G26: 0.5 | H26: Moderate | J26: =$B26 -> Panca inclinata [manubri] | K26: =IF(ISNUMBER(M26),calculateSets(M26:V26,J$3,W24,100%,$H26,$I26),1) -> 1 | L26: =IF(AND(ISNUMBER(C26),C26>0),calculateWeight(C26,$D26,$E26,$F26,$G26,0,J$3),0) -> 83 | W26: =IF(ISNUMBER(M26),calculateEffectiveRepetitions(M26:V26),0) -> 0 | X26: =IF(AND(ISNUMBER(M26),ISNUMBER(L26)),calculateHVL(M26:V26,L26),0) -> 0 | Y26: =IF(AND(ISNUMBER(L26),ISNUMBER(M26)),calculate1RM(L26,M26),0) -> 0 | Z26: =J26 -> Panca inclinata [manubri] | AA26: =IF(ISNUMBER(AC26),calculateSets(AC26:AL26,Z$3,AM24,100%,$H26,$I26),1) -> 1 | AB26: =IF(AND(ISNUMBER(Y26),Y26>0),calculateWeight(Y26,$D26,$E26,$F26,$G26,L26,Z$3),0) -> 0 | AM26: =IF(ISNUMBER(AC26),calculateEffectiveRepetitions(AC26:AL26),0) -> 0 | AN26: =IF(AND(ISNUMBER(AC26),ISNUMBER(AB26)),calculateHVL(AC26:AL26,AB26),0) -> 0 | AO26: =IF(AND(ISNUMBER(AB26),ISNUMBER(AC26)),calculate1RM(AB26,AC26),0) -> 0 | AP26: =Z26 -> Panca inclinata [manubri] | AQ26: =IF(ISNUMBER(AS26),calculateSets(AS26:BB26,AP$3,BC24,100%,$H26,$I26),1) -> 1 | AR26: =IF(AND(ISNUMBER(AO26),AO26>0),calculateWeight(AO26,$D26,$E26,$F26,$G26,AB26,AP$3),0) -> 0 | BC26: =IF(ISNUMBER(AS26),calculateEffectiveRepetitions(AS26:BB26),0) -> 0 | BD26: =IF(AND(ISNUMBER(AS26),ISNUMBER(AR26)),calculateHVL(AS26:BB26,AR26),0) -> 0 | BE26: =IF(AND(ISNUMBER(AR26),ISNUMBER(AS26)),calculate1RM(AR26,AS26),0) -> 0 | BF26: =AP26 -> Panca inclinata [manubri] | BG26: =IF(ISNUMBER(BI26),calculateSets(BI26:BR26,BF$3,BS24,100%,$H26,$I26),1) -> 1 | BH26: =IF(AND(ISNUMBER(BE26),BE26>0),calculateWeight(BE26,$D26,$E26,$F26,$G26,AR26,BF$3),0) -> 0 | BS26: =IF(ISNUMBER(BI26),calculateEffectiveRepetitions(BI26:BR26),0) -> 0 | BT26: =IF(AND(ISNUMBER(BI26),ISNUMBER(BH26)),calculateHVL(BI26:BR26,BH26),0) -> 0 | BU26: =IF(AND(ISNUMBER(BH26),ISNUMBER(BI26)),calculate1RM(BH26,BI26),0) -> 0
B27: Panca inclinata | C27: 100 | D27: 0.83 | E27: 0.89 | F27: 100 | G27: 0.5 | H27: Moderate | J27: =$B27 -> Panca inclinata | K27: =IF(ISNUMBER(M27),calculateSets(M27:V27,J$3,W25,100%,$H27,$I27),1) -> 1 | L27: =IF(AND(ISNUMBER(C27),C27>0),calculateWeight(C27,$D27,$E27,$F27,$G27,0,J$3),0) -> 83 | W27: =IF(ISNUMBER(M27),calculateEffectiveRepetitions(M27:V27),0) -> 0 | X27: =IF(AND(ISNUMBER(M27),ISNUMBER(L27)),calculateHVL(M27:V27,L27),0) -> 0 | Y27: =IF(AND(ISNUMBER(L27),ISNUMBER(M27)),calculate1RM(L27,M27),0) -> 0 | Z27: =J27 -> Panca inclinata | AA27: =IF(ISNUMBER(AC27),calculateSets(AC27:AL27,Z$3,AM25,100%,$H27,$I27),1) -> 1 | AB27: =IF(AND(ISNUMBER(Y27),Y27>0),calculateWeight(Y27,$D27,$E27,$F27,$G27,L27,Z$3),0) -> 0 | AM27: =IF(ISNUMBER(AC27),calculateEffectiveRepetitions(AC27:AL27),0) -> 0 | AN27: =IF(AND(ISNUMBER(AC27),ISNUMBER(AB27)),calculateHVL(AC27:AL27,AB27),0) -> 0 | AO27: =IF(AND(ISNUMBER(AB27),ISNUMBER(AC27)),calculate1RM(AB27,AC27),0) -> 0 | AP27: =Z27 -> Panca inclinata | AQ27: =IF(ISNUMBER(AS27),calculateSets(AS27:BB27,AP$3,BC25,100%,$H27,$I27),1) -> 1 | AR27: =IF(AND(ISNUMBER(AO27),AO27>0),calculateWeight(AO27,$D27,$E27,$F27,$G27,AB27,AP$3),0) -> 0 | BC27: =IF(ISNUMBER(AS27),calculateEffectiveRepetitions(AS27:BB27),0) -> 0 | BD27: =IF(AND(ISNUMBER(AS27),ISNUMBER(AR27)),calculateHVL(AS27:BB27,AR27),0) -> 0 | BE27: =IF(AND(ISNUMBER(AR27),ISNUMBER(AS27)),calculate1RM(AR27,AS27),0) -> 0 | BF27: =AP27 -> Panca inclinata | BG27: =IF(ISNUMBER(BI27),calculateSets(BI27:BR27,BF$3,BS25,100%,$H27,$I27),1) -> 1 | BH27: =IF(AND(ISNUMBER(BE27),BE27>0),calculateWeight(BE27,$D27,$E27,$F27,$G27,AR27,BF$3),0) -> 0 | BS27: =IF(ISNUMBER(BI27),calculateEffectiveRepetitions(BI27:BR27),0) -> 0 | BT27: =IF(AND(ISNUMBER(BI27),ISNUMBER(BH27)),calculateHVL(BI27:BR27,BH27),0) -> 0 | BU27: =IF(AND(ISNUMBER(BH27),ISNUMBER(BI27)),calculate1RM(BH27,BI27),0) -> 0
B28: Pulley | C28: 100 | D28: 0.83 | E28: 0.89 | F28: 100 | G28: 0.5 | H28: Moderate | J28: =$B28 -> Pulley | K28: =IF(ISNUMBER(M28),calculateSets(M28:V28,J$3,0,50%,$H28,$I28),1) -> 1 | L28: =IF(AND(ISNUMBER(C28),C28>0),calculateWeight(C28,$D28,$E28,$F28,$G28,0,J$3),0) -> 83 | W28: =IF(ISNUMBER(M28),calculateEffectiveRepetitions(M28:V28),0) -> 0 | X28: =IF(AND(ISNUMBER(M28),ISNUMBER(L28)),calculateHVL(M28:V28,L28),0) -> 0 | Y28: =IF(AND(ISNUMBER(L28),ISNUMBER(M28)),calculate1RM(L28,M28),0) -> 0 | Z28: =J28 -> Pulley | AA28: =IF(ISNUMBER(AC28),calculateSets(AC28:AL28,Z$3,0,50%,$H28,$I28),1) -> 1 | AB28: =IF(AND(ISNUMBER(Y28),Y28>0),calculateWeight(Y28,$D28,$E28,$F28,$G28,L28,Z$3),0) -> 0 | AM28: =IF(ISNUMBER(AC28),calculateEffectiveRepetitions(AC28:AL28),0) -> 0 | AN28: =IF(AND(ISNUMBER(AC28),ISNUMBER(AB28)),calculateHVL(AC28:AL28,AB28),0) -> 0 | AO28: =IF(AND(ISNUMBER(AB28),ISNUMBER(AC28)),calculate1RM(AB28,AC28),0) -> 0 | AP28: =Z28 -> Pulley | AQ28: =IF(ISNUMBER(AS28),calculateSets(AS28:BB28,AP$3,0,50%,$H28,$I28),1) -> 1 | AR28: =IF(AND(ISNUMBER(AO28),AO28>0),calculateWeight(AO28,$D28,$E28,$F28,$G28,AB28,AP$3),0) -> 0 | BC28: =IF(ISNUMBER(AS28),calculateEffectiveRepetitions(AS28:BB28),0) -> 0 | BD28: =IF(AND(ISNUMBER(AS28),ISNUMBER(AR28)),calculateHVL(AS28:BB28,AR28),0) -> 0 | BE28: =IF(AND(ISNUMBER(AR28),ISNUMBER(AS28)),calculate1RM(AR28,AS28),0) -> 0 | BF28: =AP28 -> Pulley | BG28: =IF(ISNUMBER(BI28),calculateSets(BI28:BR28,BF$3,0,50%,$H28,$I28),1) -> 1 | BH28: =IF(AND(ISNUMBER(BE28),BE28>0),calculateWeight(BE28,$D28,$E28,$F28,$G28,AR28,BF$3),0) -> 0 | BS28: =IF(ISNUMBER(BI28),calculateEffectiveRepetitions(BI28:BR28),0) -> 0 | BT28: =IF(AND(ISNUMBER(BI28),ISNUMBER(BH28)),calculateHVL(BI28:BR28,BH28),0) -> 0 | BU28: =IF(AND(ISNUMBER(BH28),ISNUMBER(BI28)),calculate1RM(BH28,BI28),0) -> 0
B29: 7x7x7 | C29: 12.5 | D29: 0.83 | E29: 0.89 | F29: 100 | G29: 0.5 | H29: Moderate | J29: =$B29 -> 7x7x7 | K29: =IF(ISNUMBER(M29),calculateSets(M29:V29,J$3,0,50%,$H29,$I29),1) -> 1 | L29: =IF(AND(ISNUMBER(C29),C29>0),calculateWeight(C29,$D29,$E29,$F29,$G29,0,J$3),0) -> 10.5 | W29: =IF(ISNUMBER(M29),calculateEffectiveRepetitions(M29:V29),0) -> 0 | X29: =IF(AND(ISNUMBER(M29),ISNUMBER(L29)),calculateHVL(M29:V29,L29),0) -> 0 | Y29: =IF(AND(ISNUMBER(L29),ISNUMBER(M29)),calculate1RM(L29,M29),0) -> 0 | Z29: =J29 -> 7x7x7 | AA29: =IF(ISNUMBER(AC29),calculateSets(AC29:AL29,Z$3,0,50%,$H29,$I29),1) -> 1 | AB29: =IF(AND(ISNUMBER(Y29),Y29>0),calculateWeight(Y29,$D29,$E29,$F29,$G29,L29,Z$3),0) -> 0 | AM29: =IF(ISNUMBER(AC29),calculateEffectiveRepetitions(AC29:AL29),0) -> 0 | AN29: =IF(AND(ISNUMBER(AC29),ISNUMBER(AB29)),calculateHVL(AC29:AL29,AB29),0) -> 0 | AO29: =IF(AND(ISNUMBER(AB29),ISNUMBER(AC29)),calculate1RM(AB29,AC29),0) -> 0 | AP29: =Z29 -> 7x7x7 | AQ29: =IF(ISNUMBER(AS29),calculateSets(AS29:BB29,AP$3,0,50%,$H29,$I29),1) -> 1 | AR29: =IF(AND(ISNUMBER(AO29),AO29>0),calculateWeight(AO29,$D29,$E29,$F29,$G29,AB29,AP$3),0) -> 0 | BC29: =IF(ISNUMBER(AS29),calculateEffectiveRepetitions(AS29:BB29),0) -> 0 | BD29: =IF(AND(ISNUMBER(AS29),ISNUMBER(AR29)),calculateHVL(AS29:BB29,AR29),0) -> 0 | BE29: =IF(AND(ISNUMBER(AR29),ISNUMBER(AS29)),calculate1RM(AR29,AS29),0) -> 0 | BF29: =AP29 -> 7x7x7 | BG29: =IF(ISNUMBER(BI29),calculateSets(BI29:BR29,BF$3,0,50%,$H29,$I29),1) -> 1 | BH29: =IF(AND(ISNUMBER(BE29),BE29>0),calculateWeight(BE29,$D29,$E29,$F29,$G29,AR29,BF$3),0) -> 0 | BS29: =IF(ISNUMBER(BI29),calculateEffectiveRepetitions(BI29:BR29),0) -> 0 | BT29: =IF(AND(ISNUMBER(BI29),ISNUMBER(BH29)),calculateHVL(BI29:BR29,BH29),0) -> 0 | BU29: =IF(AND(ISNUMBER(BH29),ISNUMBER(BI29)),calculate1RM(BH29,BI29),0) -> 0
J30: =J3 -> Week 1 | Z30: =Z21 -> Week 2 | AP30: =AP21 -> Week 3 | BF30: =BF21 -> Week 4
J31: Exercise | K31: Sets | L31: Weight | M31: Reps | W31: Eff. Reps | X31: HVL | Y31: 1RM | Z31: Exercise | AA31: Sets | AB31: Weight | AC31: Reps | AM31: Eff. Reps | AN31: HVL | AO31: 1RM | AP31: Exercise | AQ31: Sets | AR31: Weight | AS31: Reps | BC31: Eff. Reps | BD31: HVL | BE31: 1RM | BF31: Exercise | BG31: Sets | BH31: Weight | BI31: Reps | BS31: Eff. Reps | BT31: HVL | BU31: 1RM
B32: Exercise | C32: 1RM | D32: 1st Rep Range | F32: Weight Stack Set | G32: Rounding | H32: Training Volume | I32: Maximum Sets
C33: 100 | D33: 0.83 | E33: 0.89 | F33: 100 | G33: 0.5 | H33: Moderate | J33: =$B33 | K33: =IF(ISNUMBER(M33),calculateSets(M33:V33,J$3,W28,100%,$H33,$I33),1) -> 1 | L33: =IF(AND(ISNUMBER(C33),C33>0),calculateWeight(C33,$D33,$E33,$F33,$G33,0,J$3),0) -> 83 | W33: =IF(ISNUMBER(M33),calculateEffectiveRepetitions(M33:V33),0) -> 0 | X33: =IF(AND(ISNUMBER(M33),ISNUMBER(L33)),calculateHVL(M33:V33,L33),0) -> 0 | Y33: =IF(AND(ISNUMBER(L33),ISNUMBER(M33)),calculate1RM(L33,M33),0) -> 0 | Z33: =J33 | AA33: =IF(ISNUMBER(AC33),calculateSets(AC33:AL33,Z$3,AM28,100%,$H33,$I33),1) -> 1 | AB33: =IF(AND(ISNUMBER(Y33),Y33>0),calculateWeight(Y33,$D33,$E33,$F33,$G33,L33,Z$3),0) -> 0 | AM33: =IF(ISNUMBER(AC33),calculateEffectiveRepetitions(AC33:AL33),0) -> 0 | AN33: =IF(AND(ISNUMBER(AC33),ISNUMBER(AB33)),calculateHVL(AC33:AL33,AB33),0) -> 0 | AO33: =IF(AND(ISNUMBER(AB33),ISNUMBER(AC33)),calculate1RM(AB33,AC33),0) -> 0 | AP33: =Z33 | AQ33: =IF(ISNUMBER(AS33),calculateSets(AS33:BB33,AP$3,BC28,100%,$H33,$I33),1) -> 1 | AR33: =IF(AND(ISNUMBER(AO33),AO33>0),calculateWeight(AO33,$D33,$E33,$F33,$G33,AB33,AP$3),0) -> 0 | BC33: =IF(ISNUMBER(AS33),calculateEffectiveRepetitions(AS33:BB33),0) -> 0 | BD33: =IF(AND(ISNUMBER(AS33),ISNUMBER(AR33)),calculateHVL(AS33:BB33,AR33),0) -> 0 | BE33: =IF(AND(ISNUMBER(AR33),ISNUMBER(AS33)),calculate1RM(AR33,AS33),0) -> 0 | BF33: =AP33 | BG33: =IF(ISNUMBER(BI33),calculateSets(BI33:BR33,BF$3,BS28,100%,$H33,$I33),1) -> 1 | BH33: =IF(AND(ISNUMBER(BE33),BE33>0),calculateWeight(BE33,$D33,$E33,$F33,$G33,AR33,BF$3),0) -> 0 | BS33: =IF(ISNUMBER(BI33),calculateEffectiveRepetitions(BI33:BR33),0) -> 0 | BT33: =IF(AND(ISNUMBER(BI33),ISNUMBER(BH33)),calculateHVL(BI33:BR33,BH33),0) -> 0 | BU33: =IF(AND(ISNUMBER(BH33),ISNUMBER(BI33)),calculate1RM(BH33,BI33),0) -> 0
C34: 100 | D34: 0.83 | E34: 0.89 | F34: 100 | G34: 0.5 | H34: Moderate | J34: =$B34 | K34: =IF(ISNUMBER(M34),calculateSets(M34:V34,J$3,W29,100%,$H34,$I34),1) -> 1 | L34: =IF(AND(ISNUMBER(C34),C34>0),calculateWeight(C34,$D34,$E34,$F34,$G34,0,J$3),0) -> 83 | W34: =IF(ISNUMBER(M34),calculateEffectiveRepetitions(M34:V34),0) -> 0 | X34: =IF(AND(ISNUMBER(M34),ISNUMBER(L34)),calculateHVL(M34:V34,L34),0) -> 0 | Y34: =IF(AND(ISNUMBER(L34),ISNUMBER(M34)),calculate1RM(L34,M34),0) -> 0 | Z34: =J34 | AA34: =IF(ISNUMBER(AC34),calculateSets(AC34:AL34,Z$3,AM29,100%,$H34,$I34),1) -> 1 | AB34: =IF(AND(ISNUMBER(Y34),Y34>0),calculateWeight(Y34,$D34,$E34,$F34,$G34,L34,Z$3),0) -> 0 | AM34: =IF(ISNUMBER(AC34),calculateEffectiveRepetitions(AC34:AL34),0) -> 0 | AN34: =IF(AND(ISNUMBER(AC34),ISNUMBER(AB34)),calculateHVL(AC34:AL34,AB34),0) -> 0 | AO34: =IF(AND(ISNUMBER(AB34),ISNUMBER(AC34)),calculate1RM(AB34,AC34),0) -> 0 | AP34: =Z34 | AQ34: =IF(ISNUMBER(AS34),calculateSets(AS34:BB34,AP$3,BC29,100%,$H34,$I34),1) -> 1 | AR34: =IF(AND(ISNUMBER(AO34),AO34>0),calculateWeight(AO34,$D34,$E34,$F34,$G34,AB34,AP$3),0) -> 0 | BC34: =IF(ISNUMBER(AS34),calculateEffectiveRepetitions(AS34:BB34),0) -> 0 | BD34: =IF(AND(ISNUMBER(AS34),ISNUMBER(AR34)),calculateHVL(AS34:BB34,AR34),0) -> 0 | BE34: =IF(AND(ISNUMBER(AR34),ISNUMBER(AS34)),calculate1RM(AR34,AS34),0) -> 0 | BF34: =AP34 | BG34: =IF(ISNUMBER(BI34),calculateSets(BI34:BR34,BF$3,BS29,100%,$H34,$I34),1) -> 1 | BH34: =IF(AND(ISNUMBER(BE34),BE34>0),calculateWeight(BE34,$D34,$E34,$F34,$G34,AR34,BF$3),0) -> 0 | BS34: =IF(ISNUMBER(BI34),calculateEffectiveRepetitions(BI34:BR34),0) -> 0 | BT34: =IF(AND(ISNUMBER(BI34),ISNUMBER(BH34)),calculateHVL(BI34:BR34,BH34),0) -> 0 | BU34: =IF(AND(ISNUMBER(BH34),ISNUMBER(BI34)),calculate1RM(BH34,BI34),0) -> 0
C35: 100 | D35: 0.83 | E35: 0.89 | F35: 100 | G35: 0.5 | H35: Moderate | J35: =$B35 | K35: =IF(ISNUMBER(M35),calculateSets(M35:V35,J$3,0,50%,$H35,$I35),1) -> 1 | L35: =IF(AND(ISNUMBER(C35),C35>0),calculateWeight(C35,$D35,$E35,$F35,$G35,0,J$3),0) -> 83 | W35: =IF(ISNUMBER(M35),calculateEffectiveRepetitions(M35:V35),0) -> 0 | X35: =IF(AND(ISNUMBER(M35),ISNUMBER(L35)),calculateHVL(M35:V35,L35),0) -> 0 | Y35: =IF(AND(ISNUMBER(L35),ISNUMBER(M35)),calculate1RM(L35,M35),0) -> 0 | Z35: =J35 | AA35: =IF(ISNUMBER(AC35),calculateSets(AC35:AL35,Z$3,0,50%,$H35,$I35),1) -> 1 | AB35: =IF(AND(ISNUMBER(Y35),Y35>0),calculateWeight(Y35,$D35,$E35,$F35,$G35,L35,Z$3),0) -> 0 | AM35: =IF(ISNUMBER(AC35),calculateEffectiveRepetitions(AC35:AL35),0) -> 0 | AN35: =IF(AND(ISNUMBER(AC35),ISNUMBER(AB35)),calculateHVL(AC35:AL35,AB35),0) -> 0 | AO35: =IF(AND(ISNUMBER(AB35),ISNUMBER(AC35)),calculate1RM(AB35,AC35),0) -> 0 | AP35: =Z35 | AQ35: =IF(ISNUMBER(AS35),calculateSets(AS35:BB35,AP$3,0,50%,$H35,$I35),1) -> 1 | AR35: =IF(AND(ISNUMBER(AO35),AO35>0),calculateWeight(AO35,$D35,$E35,$F35,$G35,AB35,AP$3),0) -> 0 | BC35: =IF(ISNUMBER(AS35),calculateEffectiveRepetitions(AS35:BB35),0) -> 0 | BD35: =IF(AND(ISNUMBER(AS35),ISNUMBER(AR35)),calculateHVL(AS35:BB35,AR35),0) -> 0 | BE35: =IF(AND(ISNUMBER(AR35),ISNUMBER(AS35)),calculate1RM(AR35,AS35),0) -> 0 | BF35: =AP35 | BG35: =IF(ISNUMBER(BI35),calculateSets(BI35:BR35,BF$3,0,50%,$H35,$I35),1) -> 1 | BH35: =IF(AND(ISNUMBER(BE35),BE35>0),calculateWeight(BE35,$D35,$E35,$F35,$G35,AR35,BF$3),0) -> 0 | BS35: =IF(ISNUMBER(BI35),calculateEffectiveRepetitions(BI35:BR35),0) -> 0 | BT35: =IF(AND(ISNUMBER(BI35),ISNUMBER(BH35)),calculateHVL(BI35:BR35,BH35),0) -> 0 | BU35: =IF(AND(ISNUMBER(BH35),ISNUMBER(BI35)),calculate1RM(BH35,BI35),0) -> 0
C36: 100 | D36: 0.83 | E36: 0.89 | F36: 100 | G36: 0.5 | H36: Moderate | J36: =$B36 | K36: =IF(ISNUMBER(M36),calculateSets(M36:V36,J$3,SUM(W28,W33)*50%,100%,$H36,$I36),1) -> 1 | L36: =IF(AND(ISNUMBER(C36),C36>0),calculateWeight(C36,$D36,$E36,$F36,$G36,0,J$3),0) -> 83 | W36: =IF(ISNUMBER(M36),calculateEffectiveRepetitions(M36:V36),0) -> 0 | X36: =IF(AND(ISNUMBER(M36),ISNUMBER(L36)),calculateHVL(M36:V36,L36),0) -> 0 | Y36: =IF(AND(ISNUMBER(L36),ISNUMBER(M36)),calculate1RM(L36,M36),0) -> 0 | Z36: =J36 | AA36: =IF(ISNUMBER(AC36),calculateSets(AC36:AL36,Z$3,SUM(AM28,AM33)*50%,100%,$H36,$I36),1) -> 1 | AB36: =IF(AND(ISNUMBER(Y36),Y36>0),calculateWeight(Y36,$D36,$E36,$F36,$G36,L36,Z$3),0) -> 0 | AM36: =IF(ISNUMBER(AC36),calculateEffectiveRepetitions(AC36:AL36),0) -> 0 | AN36: =IF(AND(ISNUMBER(AC36),ISNUMBER(AB36)),calculateHVL(AC36:AL36,AB36),0) -> 0 | AO36: =IF(AND(ISNUMBER(AB36),ISNUMBER(AC36)),calculate1RM(AB36,AC36),0) -> 0 | AP36: =Z36 | AQ36: =IF(ISNUMBER(AS36),calculateSets(AS36:BB36,AP$3,SUM(BC28,BC33)*50%,100%,$H36,$I36),1) -> 1 | AR36: =IF(AND(ISNUMBER(AO36),AO36>0),calculateWeight(AO36,$D36,$E36,$F36,$G36,AB36,AP$3),0) -> 0 | BC36: =IF(ISNUMBER(AS36),calculateEffectiveRepetitions(AS36:BB36),0) -> 0 | BD36: =IF(AND(ISNUMBER(AS36),ISNUMBER(AR36)),calculateHVL(AS36:BB36,AR36),0) -> 0 | BE36: =IF(AND(ISNUMBER(AR36),ISNUMBER(AS36)),calculate1RM(AR36,AS36),0) -> 0 | BF36: =AP36 | BG36: =IF(ISNUMBER(BI36),calculateSets(BI36:BR36,BF$3,SUM(BS28,BS33)*50%,100%,$H36,$I36),1) -> 1 | BH36: =IF(AND(ISNUMBER(BE36),BE36>0),calculateWeight(BE36,$D36,$E36,$F36,$G36,AR36,BF$3),0) -> 0 | BS36: =IF(ISNUMBER(BI36),calculateEffectiveRepetitions(BI36:BR36),0) -> 0 | BT36: =IF(AND(ISNUMBER(BI36),ISNUMBER(BH36)),calculateHVL(BI36:BR36,BH36),0) -> 0 | BU36: =IF(AND(ISNUMBER(BH36),ISNUMBER(BI36)),calculate1RM(BH36,BI36),0) -> 0
